{
    "status": "Fix Released", 
    "last_updated": "2010-10-25 20:11:46.353364+00:00", 
    "description": "When running nova-network, the periodic task execution fails with an AttributeError, because the wrong value has been passed into db.fixed_ip_disassociate_all_by_timeout:\n\n2010-10-02 12:44:56+0100 [-] Unhandled Error\n        Traceback (most recent call last):\n          File \"/usr/lib/python2.6/dist-packages/twisted/internet/defer.py\", line 944, in unwindGenerator\n            return _inlineCallbacks(None, f(*args, **kwargs), Deferred())\n          File \"/usr/lib/python2.6/dist-packages/twisted/internet/defer.py\", line 823, in _inlineCallbacks\n            result = g.send(result)\n          File \"/home/emellor/openstack/nova/xenapi/nova/service.py\", line 149, in periodic_tasks\n            yield self.manager.periodic_tasks(context)\n          File \"/usr/lib/python2.6/dist-packages/twisted/internet/defer.py\", line 944, in unwindGenerator\n            return _inlineCallbacks(None, f(*args, **kwargs), Deferred())\n        --- <exception caught here> ---\n          File \"/usr/lib/python2.6/dist-packages/twisted/internet/defer.py\", line 823, in _inlineCallbacks\n            result = g.send(result)\n          File \"/home/emellor/openstack/nova/xenapi/nova/network/manager.py\", line 235, in periodic_tasks\n            time)\n          File \"/home/emellor/openstack/nova/xenapi/nova/db/api.py\", line 209, in fixed_ip_disassociate_all_by_timeout\n            return IMPL.fixed_ip_disassociate_all_by_timeout(context, host, time)\n          File \"/home/emellor/openstack/nova/xenapi/nova/db/sqlalchemy/api.py\", line 90, in wrapper\n            if not is_admin_context(args[0]):\n          File \"/home/emellor/openstack/nova/xenapi/nova/db/sqlalchemy/api.py\", line 44, in is_admin_context\n            return context.is_admin\n        exceptions.AttributeError: 'VlanManager' object has no attribute 'is_admin'", 
    "tags": [], 
    "importance": "Undecided", 
    "heat": 6, 
    "link": "https://bugs.launchpad.net/nova/+bug/653560", 
    "owner": "https://api.launchpad.net/1.0/~ewanmellor", 
    "id": 653560, 
    "index": 3202, 
    "openned": "2010-10-02 12:08:59.328496+00:00", 
    "created": "2010-10-02 12:08:59.328496+00:00", 
    "title": "AttributeError in VlanManager.periodic_tasks", 
    "comments": [
        {
            "content": "When running nova-network, the periodic task execution fails with an AttributeError, because the wrong value has been passed into db.fixed_ip_disassociate_all_by_timeout:\n\n2010-10-02 12:44:56+0100 [-] Unhandled Error\n        Traceback (most recent call last):\n          File \"/usr/lib/python2.6/dist-packages/twisted/internet/defer.py\", line 944, in unwindGenerator\n            return _inlineCallbacks(None, f(*args, **kwargs), Deferred())\n          File \"/usr/lib/python2.6/dist-packages/twisted/internet/defer.py\", line 823, in _inlineCallbacks\n            result = g.send(result)\n          File \"/home/emellor/openstack/nova/xenapi/nova/service.py\", line 149, in periodic_tasks\n            yield self.manager.periodic_tasks(context)\n          File \"/usr/lib/python2.6/dist-packages/twisted/internet/defer.py\", line 944, in unwindGenerator\n            return _inlineCallbacks(None, f(*args, **kwargs), Deferred())\n        --- <exception caught here> ---\n          File \"/usr/lib/python2.6/dist-packages/twisted/internet/defer.py\", line 823, in _inlineCallbacks\n            result = g.send(result)\n          File \"/home/emellor/openstack/nova/xenapi/nova/network/manager.py\", line 235, in periodic_tasks\n            time)\n          File \"/home/emellor/openstack/nova/xenapi/nova/db/api.py\", line 209, in fixed_ip_disassociate_all_by_timeout\n            return IMPL.fixed_ip_disassociate_all_by_timeout(context, host, time)\n          File \"/home/emellor/openstack/nova/xenapi/nova/db/sqlalchemy/api.py\", line 90, in wrapper\n            if not is_admin_context(args[0]):\n          File \"/home/emellor/openstack/nova/xenapi/nova/db/sqlalchemy/api.py\", line 44, in is_admin_context\n            return context.is_admin\n        exceptions.AttributeError: 'VlanManager' object has no attribute 'is_admin'", 
            "date_created": "2010-10-02 12:08:59.328496+00:00", 
            "author": "https://api.launchpad.net/1.0/~ewanmellor"
        }
    ], 
    "closed": "2010-10-25 20:11:45.560554+00:00"
}