{
    "status": "In Progress", 
    "last_updated": "2017-08-03 08:46:17.328549+00:00", 
    "description": "This is from code inspection only.\n\nComputeManager.resize_instance does:\n\n  with self._error_out_instance_on_exception(context, instance,\n                                             quotas=quotas):\n      ...stuff...\n\n      self.compute_rpcapi.finish_resize(context, instance,\n                    migration, image, disk_info,\n                    migration.dest_compute, reservations=quotas.reservations)\n\n      ... Responsibility for the instance has now been punted to the destination, but...\n\n      self._notify_about_instance_usage(context, instance, \"resize.end\",\n                                              network_info=network_info)\n\n      compute_utils.notify_about_instance_action(context, instance,\n                   self.host, action=fields.NotificationAction.RESIZE,\n                   phase=fields.NotificationPhase.END)\n      self.instance_events.clear_events_for_instance(instance)\n\nThe problem is that a failure in anything after the cast to finish_resize will cause the instance to be put in an error state and its quotas rolled back. This would not be correct, as any error here would be purely ephemeral. The resize operation will continue on the destination regardless, so this would almost certainly result in an inconsistent state.", 
    "tags": [], 
    "importance": "Undecided", 
    "heat": 6, 
    "link": "https://bugs.launchpad.net/nova/+bug/1688228", 
    "owner": "https://api.launchpad.net/1.0/~mbooth-9", 
    "id": 1688228, 
    "index": 8104, 
    "openned": "2017-05-04 10:57:56.099588+00:00", 
    "created": "2017-05-04 10:57:56.099588+00:00", 
    "title": "Failure in resize_instance after cast to finish_resize still sets instance error state", 
    "comments": [
        {
            "content": "This is from code inspection only.\n\nComputeManager.resize_instance does:\n\n  with self._error_out_instance_on_exception(context, instance,\n                                             quotas=quotas):\n      ...stuff...\n\n      self.compute_rpcapi.finish_resize(context, instance,\n                    migration, image, disk_info,\n                    migration.dest_compute, reservations=quotas.reservations)\n\n      ... Responsibility for the instance has now been punted to the destination, but...\n\n      self._notify_about_instance_usage(context, instance, \"resize.end\",\n                                              network_info=network_info)\n\n      compute_utils.notify_about_instance_action(context, instance,\n                   self.host, action=fields.NotificationAction.RESIZE,\n                   phase=fields.NotificationPhase.END)\n      self.instance_events.clear_events_for_instance(instance)\n\nThe problem is that a failure in anything after the cast to finish_resize will cause the instance to be put in an error state and its quotas rolled back. This would not be correct, as any error here would be purely ephemeral. The resize operation will continue on the destination regardless, so this would almost certainly result in an inconsistent state.", 
            "date_created": "2017-05-04 10:57:56.099588+00:00", 
            "author": "https://api.launchpad.net/1.0/~mbooth-9"
        }, 
        {
            "content": "Fix proposed to branch: master\nReview: https://review.openstack.org/462499", 
            "date_created": "2017-05-04 11:16:50.914353+00:00", 
            "author": "https://api.launchpad.net/1.0/~hudson-openstack"
        }, 
        {
            "content": "Change abandoned by Matthew Booth (<email address hidden>) on branch: master\nReview: https://review.openstack.org/462499\nReason: This came loose from my series fixing this.", 
            "date_created": "2017-08-03 08:46:16.921805+00:00", 
            "author": "https://api.launchpad.net/1.0/~hudson-openstack"
        }
    ]
}