{
    "status": "Invalid", 
    "last_updated": "2013-12-31 01:36:13.019477+00:00", 
    "description": "Call me perplexed.\n\n/path/to/nova-2013.2. # testr run \n\nyields\n\nRan 18852 (+18610) tests in 330.945s (+325.799s)\nFAILED (id=6, failures=1150 (+1150), skips=10)\n\nEeeer, hmm.  Somethings are awry.  Let's edit .testr.conf to run testr of nova/tests/api.\n\n/path/to/nova-2013.2. # testr run --parallel\n\nRan 6004 tests in 66.374s\nFAILED (id=0, failures=380)\n\nTraceback (most recent call last):\n  File \"/usr/lib64/python2.7/site-packages/stevedore/extension.py\", line 89, in _load_plugins\n.......\n    raise VersionConflict(dist,req) # XXX put more info here\nVersionConflict: (jsonschema 0.7 (/usr/lib64/python2.7/site-packages), Requirement.parse('jsonschema>=1.3.0,!=1.4.0'))\nCould not load 'shelve': (jsonschema 0.7 (/usr/lib64/python2.7/site-packages), Requirement.parse('jsonschema>=1.3.0,!=1.4.0'))\n(jsonschema 0.7 (/usr/lib64/python2.7/site-packages), Requirement.parse('jsonschema>=1.3.0,!=1.4.0'))\n\nShall flesh this out later, firstly let's pin the failing sub-folders to nova/tests\n\nEdit to ./nova/tests/image\n\n/path/to/nova-2013.2. # testr run --parallel\n\nFAIL: process-returncode\ntags: worker-1\n----------------------------------------------------------------------\nBinary content:\n  traceback (test/plain; charset=\"utf8\")\nRan 115 (-2889) tests in 4.257s (-62.066s)\nFAILED (id=1, failures=7 (-373))\n\nMore of the Requirement.parse('jsonschema>=1.3.0,!=1.4.0')) 'stuff', PLUS\n\ntest_download_module_filesystem_match,\ntest_download_module_mountpoints, \ntest_download_module_no_filesystem_match\n\nyield\n=============================\n  File \"/usr/lib64/python2.7/site-packages/oslo/config/cfg.py\", line 2068, in _get_group\n    raise NoSuchGroupError(group_name)\nNoSuchGroupError: no such group: image_file_url\n\n............................................\n\nEdit to ./nova/tests/integrated, and GASP\n\n  traceback (test/plain; charset=\"utf8\")\nRan 1694 (+1635) tests in 41.188s (+36.932s)\nFAILED (id=2, failures=849 (+842))\n\nand I believe 849 instances of\n\nTraceback (most recent call last):\n  File \"/mnt/gen2/TmpDir/portage/sys-cluster/nova-2013.2-r1/work/nova-2013.2/nova/tests/integrated/v3/test_simple_tenant_*.py\", line 29, in setUp\n    super(SimpleTenantUsageSampleJsonTest, self).setUp()\n  File \"/mnt/gen2/TmpDir/portage/sys-cluster/nova-2013.2-r1/work/nova-2013.2/nova/tests/integrated/v3/api_sample_base.py\", line 52, in setUp\n    super(ApiSampleTestBaseV3, self).setUp()\n  File \"/mnt/gen2/TmpDir/portage/sys-cluster/nova-2013.2-r1/work/nova-2013.2/nova/tests/integrated/integrated_helpers.py\", line 87, in setUp\n    self.consoleauth = self.start_service('consoleauth')\n  File \"/mnt/gen2/TmpDir/portage/sys-cluster/nova-2013.2-r1/work/nova-2013.2/nova/test.py\", line 292, in start_service\n    svc = self.useFixture(ServiceFixture(name, host, **kwargs))\n  File \"/usr/lib64/python2.7/site-packages/testtools/testcase.py\", line 591, in useFixture\n    fixture.setUp()\n  File \"/mnt/gen2/TmpDir/portage/sys-cluster/nova-2013.2-r1/work/nova-2013.2/nova/test.py\", line 175, in setUp\n    self.service = service.Service.create(**self.kwargs)\n  File \"/mnt/gen2/TmpDir/portage/sys-cluster/nova-2013.2-r1/work/nova-2013.2/nova/service.py\", line 245, in create\n    manager = CONF.get(manager_cls, None)\n  File \"/usr/lib64/python2.7/_abcoll.py\", line 363, in get\n    return self[key]\n  File \"/usr/lib64/python2.7/site-packages/oslo/config/cfg.py\", line 1645, in __getitem__\n    return self.__getattr__(key)\n  File \"/usr/lib64/python2.7/site-packages/oslo/config/cfg.py\", line 1641, in __getattr__\n    raise NoSuchOptError(name)\nNoSuchOptError: no such option: consoleauth_manager\n\nouch\n\nEdit to ./nova/tests/pci\n\n=============================\n\n  traceback (test/plain; charset=\"utf8\")\nRan 130 (-294) tests in 3.365s (-5.777s)\nFAILED (id=4, failures=15 (+15))\n\nwith a series of tests culminating in \n\nTraceback (most recent call last):\n  File \"/mnt/gen2/TmpDir/portage/sys-cluster/nova-2013.2-r1/work/nova-2013.2/nova/test/pci/test_pci_whitelist.py\", line 59, in test_whitelist\n    parsed = pci_whitelist.PciHostDevicesWhiteList([white_list])\n  File \"/mnt/gen2/TmpDir/portage/sys-cluster/nova-2013.2-r1/work/nova-2013.2/nova/pci/pci_whitelist.py\", line 100, in __init__\n    self.spec = self._parse_white_list_from_config(whitelist_spec)\n  File \"/mnt/gen2/TmpDir/portage/sys-cluster/nova-2013.2-r1/work/nova-2013.2/nova/pci/pci_whitelist.py\", line 82, in _parse_white_list_from_config\n    raise exception.PciConfigInvalidWhitelist(reason=str(e))\nPciConfigInvalidWhitelist: Invalid PCI devices Whitelist config {'additionalProperties': False, 'required': ['product_id', 'vendor_id'], 'type': 'object', 'properties': {'vendor_id': {'pattern': '^([\\\\da-fA-F]{4})$', 'type': 'string'}, 'product_id': {'pattern': '^([\\\\da-fA-F]{4})$', 'type': 'string'}}} is not of type {u'$ref': u'#'}, u'array'\n\nthe test files were test_pci_whitelist.py & pci/test_pci_request.py.\n\nAll other subfolders of nova/tests come up ok.\n\nPYTHONPATH=../nova-2013.2-python2_7/lib/ nosetests nova/tests/test_*.py\ncomes up ok.\n\nRan 492 tests in 20.234s \\ \\ OK\n\nwhich leaves only the other 1150!.!  !!\n\nNow, observe;\n\n$ eix dev-python/jsonschema -> Installed versions:  0.7\n\nwhich is gentoo speak for the system has jsonschema-0.7 installed\n\n$ PYTHONPATH=../nova-2013.2-python2_7/lib/ nosetests nova/tests/image/ ->\n Could not load 'file': (jsonschema 0.7 (/usr/lib64/python2.7/site-packages), Requirement.parse('jsonschema>=1.3.0,!=1.4.0'))\n\nInstall 1.3.0, so\n\n$ eix dev-python/jsonschema -> Installed versions:  1.3.0\n\nAND\n\nCould not load 'file': (jsonschema 1.3.0 (/usr/lib64/python2.7/site-packages), Requirement.parse('jsonschema>=0.7,<1'))\n\ndoh!.  What a w.... of a test; give it one and it insists it wants the other.\nPlease fix them", 
    "tags": [], 
    "importance": "Undecided", 
    "heat": 6, 
    "link": "https://bugs.launchpad.net/nova/+bug/1254943", 
    "owner": "None", 
    "id": 1254943, 
    "index": 4320, 
    "created": "2013-11-26 02:21:14.301262+00:00", 
    "title": "nova-2013.2;  failures=1150 (+1150), skips=10", 
    "comments": [
        {
            "content": "Call me perplexed.\n\n/path/to/nova-2013.2. # testr run \n\nyields\n\nRan 18852 (+18610) tests in 330.945s (+325.799s)\nFAILED (id=6, failures=1150 (+1150), skips=10)\n\nEeeer, hmm.  Somethings are awry.  Let's edit .testr.conf to run testr of nova/tests/api.\n\n/path/to/nova-2013.2. # testr run --parallel\n\nRan 6004 tests in 66.374s\nFAILED (id=0, failures=380)\n\nTraceback (most recent call last):\n  File \"/usr/lib64/python2.7/site-packages/stevedore/extension.py\", line 89, in _load_plugins\n.......\n    raise VersionConflict(dist,req) # XXX put more info here\nVersionConflict: (jsonschema 0.7 (/usr/lib64/python2.7/site-packages), Requirement.parse('jsonschema>=1.3.0,!=1.4.0'))\nCould not load 'shelve': (jsonschema 0.7 (/usr/lib64/python2.7/site-packages), Requirement.parse('jsonschema>=1.3.0,!=1.4.0'))\n(jsonschema 0.7 (/usr/lib64/python2.7/site-packages), Requirement.parse('jsonschema>=1.3.0,!=1.4.0'))\n\nShall flesh this out later, firstly let's pin the failing sub-folders to nova/tests\n\nEdit to ./nova/tests/image\n\n/path/to/nova-2013.2. # testr run --parallel\n\nFAIL: process-returncode\ntags: worker-1\n----------------------------------------------------------------------\nBinary content:\n  traceback (test/plain; charset=\"utf8\")\nRan 115 (-2889) tests in 4.257s (-62.066s)\nFAILED (id=1, failures=7 (-373))\n\nMore of the Requirement.parse('jsonschema>=1.3.0,!=1.4.0')) 'stuff', PLUS\n\ntest_download_module_filesystem_match,\ntest_download_module_mountpoints, \ntest_download_module_no_filesystem_match\n\nyield\n=============================\n  File \"/usr/lib64/python2.7/site-packages/oslo/config/cfg.py\", line 2068, in _get_group\n    raise NoSuchGroupError(group_name)\nNoSuchGroupError: no such group: image_file_url\n\n............................................\n\nEdit to ./nova/tests/integrated, and GASP\n\n  traceback (test/plain; charset=\"utf8\")\nRan 1694 (+1635) tests in 41.188s (+36.932s)\nFAILED (id=2, failures=849 (+842))\n\nand I believe 849 instances of\n\nTraceback (most recent call last):\n  File \"/mnt/gen2/TmpDir/portage/sys-cluster/nova-2013.2-r1/work/nova-2013.2/nova/tests/integrated/v3/test_simple_tenant_*.py\", line 29, in setUp\n    super(SimpleTenantUsageSampleJsonTest, self).setUp()\n  File \"/mnt/gen2/TmpDir/portage/sys-cluster/nova-2013.2-r1/work/nova-2013.2/nova/tests/integrated/v3/api_sample_base.py\", line 52, in setUp\n    super(ApiSampleTestBaseV3, self).setUp()\n  File \"/mnt/gen2/TmpDir/portage/sys-cluster/nova-2013.2-r1/work/nova-2013.2/nova/tests/integrated/integrated_helpers.py\", line 87, in setUp\n    self.consoleauth = self.start_service('consoleauth')\n  File \"/mnt/gen2/TmpDir/portage/sys-cluster/nova-2013.2-r1/work/nova-2013.2/nova/test.py\", line 292, in start_service\n    svc = self.useFixture(ServiceFixture(name, host, **kwargs))\n  File \"/usr/lib64/python2.7/site-packages/testtools/testcase.py\", line 591, in useFixture\n    fixture.setUp()\n  File \"/mnt/gen2/TmpDir/portage/sys-cluster/nova-2013.2-r1/work/nova-2013.2/nova/test.py\", line 175, in setUp\n    self.service = service.Service.create(**self.kwargs)\n  File \"/mnt/gen2/TmpDir/portage/sys-cluster/nova-2013.2-r1/work/nova-2013.2/nova/service.py\", line 245, in create\n    manager = CONF.get(manager_cls, None)\n  File \"/usr/lib64/python2.7/_abcoll.py\", line 363, in get\n    return self[key]\n  File \"/usr/lib64/python2.7/site-packages/oslo/config/cfg.py\", line 1645, in __getitem__\n    return self.__getattr__(key)\n  File \"/usr/lib64/python2.7/site-packages/oslo/config/cfg.py\", line 1641, in __getattr__\n    raise NoSuchOptError(name)\nNoSuchOptError: no such option: consoleauth_manager\n\nouch\n\nEdit to ./nova/tests/pci\n\n=============================\n\n  traceback (test/plain; charset=\"utf8\")\nRan 130 (-294) tests in 3.365s (-5.777s)\nFAILED (id=4, failures=15 (+15))\n\nwith a series of tests culminating in \n\nTraceback (most recent call last):\n  File \"/mnt/gen2/TmpDir/portage/sys-cluster/nova-2013.2-r1/work/nova-2013.2/nova/test/pci/test_pci_whitelist.py\", line 59, in test_whitelist\n    parsed = pci_whitelist.PciHostDevicesWhiteList([white_list])\n  File \"/mnt/gen2/TmpDir/portage/sys-cluster/nova-2013.2-r1/work/nova-2013.2/nova/pci/pci_whitelist.py\", line 100, in __init__\n    self.spec = self._parse_white_list_from_config(whitelist_spec)\n  File \"/mnt/gen2/TmpDir/portage/sys-cluster/nova-2013.2-r1/work/nova-2013.2/nova/pci/pci_whitelist.py\", line 82, in _parse_white_list_from_config\n    raise exception.PciConfigInvalidWhitelist(reason=str(e))\nPciConfigInvalidWhitelist: Invalid PCI devices Whitelist config {'additionalProperties': False, 'required': ['product_id', 'vendor_id'], 'type': 'object', 'properties': {'vendor_id': {'pattern': '^([\\\\da-fA-F]{4})$', 'type': 'string'}, 'product_id': {'pattern': '^([\\\\da-fA-F]{4})$', 'type': 'string'}}} is not of type {u'$ref': u'#'}, u'array'\n\nthe test files were test_pci_whitelist.py & pci/test_pci_request.py.\n\nAll other subfolders of nova/tests come up ok.\n\nPYTHONPATH=../nova-2013.2-python2_7/lib/ nosetests nova/tests/test_*.py\ncomes up ok.\n\nRan 492 tests in 20.234s \\ \\ OK\n\nwhich leaves only the other 1150!.!  !!\n\nNow, observe;\n\n$ eix dev-python/jsonschema -> Installed versions:  0.7\n\nwhich is gentoo speak for the system has jsonschema-0.7 installed\n\n$ PYTHONPATH=../nova-2013.2-python2_7/lib/ nosetests nova/tests/image/ ->\n Could not load 'file': (jsonschema 0.7 (/usr/lib64/python2.7/site-packages), Requirement.parse('jsonschema>=1.3.0,!=1.4.0'))\n\nInstall 1.3.0, so\n\n$ eix dev-python/jsonschema -> Installed versions:  1.3.0\n\nAND\n\nCould not load 'file': (jsonschema 1.3.0 (/usr/lib64/python2.7/site-packages), Requirement.parse('jsonschema>=0.7,<1'))\n\ndoh!.  What a w.... of a test; give it one and it insists it wants the other.\nPlease fix them", 
            "date_created": "2013-11-26 02:21:14.301262+00:00", 
            "author": "https://api.launchpad.net/1.0/~johneed"
        }, 
        {
            "content": "oh, and pylint==0.25.2 from nova-2013.2/test-requirements.txt appears it could do with updating to >=pylint-0.25.2 since all my runs appear good with it", 
            "date_created": "2013-11-26 07:19:13.158306+00:00", 
            "author": "https://api.launchpad.net/1.0/~johneed"
        }, 
        {
            "content": "You dont have the dependencies that are needed to run the tests, please install the dependencies or run tox -epy27.", 
            "date_created": "2013-12-31 01:36:07.901216+00:00", 
            "author": "https://api.launchpad.net/1.0/~zulcss"
        }
    ]
}